Workbook
Name Slicer_City: #N/A
Name Slicer_City1: #N/A
Name Slicer_Jenis_Kelamin1: #N/A
Name Slicer_Order_Status: #N/A
Name Slicer_Payment_Method: #N/A
Name Slicer_Platform: #N/A

Sheet bahan utama
A1: Row Labels | B1: Sum of Total Sales | D1: Row Labels | E1: Count of Order ID | G1: Row Labels | H1: Average of Customer Rating | J1: Sum of Grand Total | K1: Column Labels
A2: Bawang Merah | B2: 7736625 | D2: Cancelled | E2: 0.054 | G2: BelanjaSayur App | H2: 2.9473684 | J2: Row Labels | K2: COD | L2: e-Wallet | M2: Kartu Kredit | N2: Transfer Bank | O2: Grand Total
A3: Bawang Putih | B3: 5955200 | D3: Completed | E3: 0.7475 | G3: FoodMart | H3: 2.9822335 | J3: BelanjaSayur App | K3: 7144557.5 | L3: 8489127.5 | M3: 8756247.5 | N3: 7334250 | O3: 31724182
A4: Bayam | B4: 575750 | D4: Pending | E4: 0.0335 | G4: Hijau Mart | H4: 3.0074627 | J4: FoodMart | K4: 8098127.5 | L4: 7341987.5 | M4: 7905612.5 | N4: 8158825 | O4: 31504552
A5: Brokoli | B5: 2118220 | D5: Returned | E5: 0.1385 | G5: Karirnex VegMart App | H5: 2.9853301 | J5: Hijau Mart | K5: 7452010 | L5: 8432635 | M5: 7652915 | N5: 8713842.5 | O5: 32251402
A6: Buncis | B6: 1036140 | D6: Shipped | E6: 0.0265 | G6: SayurKota Mart | H6: 2.979798 | J6: Karirnex VegMart App | K6: 8357205 | L6: 6308737.5 | M6: 9128835 | N6: 7954720 | O6: 31749498
A7: Cabai Merah | B7: 4637030 | D7: Grand Total | E7: 1 | G7: Grand Total | H7: 2.9805 | J7: SayurKota Mart | K7: 6887387.5 | L7: 8183627.5 | M7: 8139195 | N7: 9044717.5 | O7: 32254928
A8: Cabai Rawit Hijau | B8: 3247475 | J8: Grand Total | K8: 37939288 | L8: 38756115 | M8: 41582805 | N8: 41206355 | O8: 1.5948456e+08
A9: Cabai Rawit Merah | B9: 6877000 | D9: jumlah orderan tiap order status | G9: rata-rata customer rating tiap platform
A10: Daun Bawang | B10: 393157.5 | J10: grand total tiap platform dipisah berdasar tiap payment method | W10: Order Status | X10: Completed
A11: Jagung Manis | B11: 2044450
A12: Kacang Panjang | B12: 1026900 | J12: Sum of Quantity (kg) | K12: Column Labels | O12: #VALUE! | W12: Row Labels | X12: Sum of Total Sales | Y12: Average of Shipping Fee | Z12: Average of Discount Amount | AA12: Sum of Grand Total
A13: Kangkung | B13: 602750 | J13: Row Labels | K13: Laki-laki | L13: Perempuan | M13: Grand Total | W13: BelanjaSayur App | X13: 8322502.5 | Y13: 51298.305 | Z13: 237.27966 | AA13: 0.20002471
A14: Kentang | B14: 5472775 | J14: Bawang Merah | K14: 39.1 | L14: 134.5 | M14: 173.6 | W14: FoodMart | X14: 8544257.5 | Y14: 49800.676 | Z14: 350.98818 | AA14: 0.19857289
A15: Kol/Kubis | B15: 3179250 | J15: Bawang Putih | K15: 29.3 | L15: 122.1 | M15: 151.4 | W15: Hijau Mart | X15: 7922550 | Y15: 51148.026 | Z15: 289.63816 | AA15: 0.20016156
A16: Labu Siam | B16: 1540665 | D16: Row Labels | E16: Sum of Total Sales | J16: Bayam | K16: 11.8 | L16: 46.3 | M16: 58.1 | W16: Karirnex VegMart App | X16: 8570537.5 | Y16: 47510.135 | Z16: 236.19088 | AA16: 0.19301513
A17: Sawi Hijau | B17: 849900 | D17: Brokoli | E17: 2118220 | J17: Brokoli | K17: 12.7 | L17: 69.6 | M17: 82.3 | W17: SayurKota Mart | X17: 8266177.5 | Y17: 53128.289 | Z17: 342.34375 | AA17: 0.20822572
A18: Terong Ungu | B18: 1004340 | D18: Tomat Merah | E18: 2818125 | J18: Buncis | K18: 21.5 | L18: 53.3 | M18: 74.8 | W18: Grand Total | X18: 41626025 | Y18: 50593.311 | Z18: 291.58863 | AA18: 1
A19: Timun | B19: 1404810 | D19: Kol/Kubis | E19: 3179250 | J19: Cabai Merah | K19: 19.7 | L19: 82 | M19: 101.7
A20: Tomat Merah | B20: 2818125 | D20: Cabai Rawit Hijau | E20: 3247475 | J20: Cabai Rawit Hijau | K20: 10.1 | L20: 49.3 | M20: 59.4
A21: Wortel | B21: 3913000 | D21: Wortel | E21: 3913000 | J21: Cabai Rawit Merah | K21: 11.7 | L21: 48.7 | M21: 60.4
A22: Grand Total | B22: 56433562 | D22: Cabai Merah | E22: 4637030 | J22: Daun Bawang | K22: 4.3 | L22: 21.4 | M22: 25.7
D23: Kentang | E23: 5472775 | J23: Jagung Manis | K23: 41.2 | L23: 165.4 | M23: 206.6
A24: total sales tiap sayuran | D24: Bawang Putih | E24: 5955200 | J24: Kacang Panjang | K24: 19.5 | L24: 66.9 | M24: 86.4
D25: Cabai Rawit Merah | E25: 6877000 | J25: Kangkung | K25: 10.5 | L25: 50.2 | M25: 60.7
D26: Bawang Merah | E26: 7736625 | J26: Kentang | K26: 51.3 | L26: 264.7 | M26: 316 | O26: jumlah order tiap city, dikelompokkan berdasar order status, hanya 10 kota dengan jml order terbanyak
D27: Grand Total | E27: 45954700 | J27: Kol/Kubis | K27: 34.6 | L27: 202.8 | M27: 237.4
J28: Labu Siam | K28: 22.3 | L28: 126 | M28: 148.3
J29: Sawi Hijau | K29: 14.4 | L29: 42.6 | M29: 57
J30: Terong Ungu | K30: 16.5 | L30: 90.4 | M30: 106.9
J31: Timun | K31: 26.5 | L31: 102.5 | M31: 129
J32: Tomat Merah | K32: 34.3 | L32: 155.7 | M32: 190
J33: Wortel | K33: 48.1 | L33: 149.6 | M33: 197.7
J34: Grand Total | K34: 479.4 | L34: 2044 | M34: 2523.4
J36: total quantity (kg) tiap product name berdasar tiap jenis kelamin

Sheet Detail1
A1: Details for Average of Customer Rating - Product Name: Timun
A3: Order ID | B3: Order Date | C3: Customer Name | D3: City | E3: Product Name | F3: Unit Price | G3: Quantity (kg) | H3: Discount (%) | I3: Subtotal | J3: Discount Amount | K3: Total Sales | L3: Shipping Fee | M3: Grand Total | N3: Payment Method | O3: Order Status | P3: Platform | Q3: Customer Rating | R3: Jenis Kelamin
A4: ORD01002 | B4: 46021.563 | C4: Yani Santoso | D4: Pontianak | E4: Timun | F4: 11000 | G4: 1.4 | H4: 0 | I4: 15400 | J4: 0 | K4: 15400 | L4: 85000 | M4: 100400 | N4: e-Wallet | O4: Pending | P4: FoodMart | Q4: 4 | R4: Perempuan
A5: ORD01479 | B5: 46020.712 | C5: Yani Santoso | D5: Pontianak | E5: Timun | F5: 11000 | G5: 1.8 | H5: 0 | I5: 19800 | J5: 0 | K5: 19800 | L5: 85000 | M5: 104800 | N5: Transfer Bank | O5: Completed | P5: SayurKota Mart | Q5: 1 | R5: Perempuan
A6: ORD01011 | B6: 46020.556 | C6: Citra Syahputra | D6: Mamuju | E6: Timun | F6: 11000 | G6: 0.6 | H6: 0 | I6: 6600 | J6: 0 | K6: 6600 | L6: 46000 | M6: 52600 | N6: Transfer Bank | O6: Pending | P6: BelanjaSayur App | Q6: 1 | R6: Perempuan
A7: ORD01688 | B7: 46020.556 | C7: Kartika Utami | D7: Bandar Lampung | E7: Timun | F7: 11000 | G7: 2.2 | H7: 0 | I7: 24200 | J7: 0 | K7: 24200 | L7: 28000 | M7: 52200 | N7: COD | O7: Shipped | P7: Hijau Mart | Q7: 3 | R7: Perempuan
A8: ORD00873 | B8: 46016.898 | C8: Andi Setiawan | D8: Pontianak | E8: Timun | F8: 11000 | G8: 1.5 | H8: 5 | I8: 16500 | J8: 825 | K8: 15675 | L8: 85000 | M8: 100675 | N8: COD | O8: Pending | P8: SayurKota Mart | Q8: 4 | R8: Laki-laki
A9: ORD01332 | B9: 46016.566 | C9: Qori Iskandar | D9: Surabaya | E9: Timun | F9: 11000 | G9: 0.7 | H9: 5 | I9: 7700 | J9: 385 | K9: 7315 | L9: 74000 | M9: 81315 | N9: COD | O9: Shipped | P9: FoodMart | Q9: 3 | R9: Perempuan
A10: ORD00093 | B10: 46016.049 | C10: Nanda Iskandar | D10: Pontianak | E10: Timun | F10: 11000 | G10: 1.7 | H10: 5 | I10: 18700 | J10: 935 | K10: 17765 | L10: 0 | M10: 17765 | N10: Transfer Bank | O10: Completed | P10: Hijau Mart | Q10: 4 | R10: Laki-laki
A11: ORD01699 | B11: 46016.01 | C11: Aulia Syahputra | D11: Medan | E11: Timun | F11: 11000 | G11: 0.8 | H11: 5 | I11: 8800 | J11: 440 | K11: 8360 | L11: 79000 | M11: 87360 | N11: Kartu Kredit | O11: Completed | P11: SayurKota Mart | Q11: 4 | R11: Perempuan
A12: ORD01324 | B12: 46003.529 | C12: Aulia Wijaya | D12: Palangka Raya | E12: Timun | F12: 11000 | G12: 2 | H12: 5 | I12: 22000 | J12: 1100 | K12: 20900 | L12: 50000 | M12: 70900 | N12: COD | O12: Completed | P12: SayurKota Mart | Q12: 5 | R12: Perempuan
A13: ORD00626 | B13: 45996.673 | C13: Vina Setiawan | D13: Bandung | E13: Timun | F13: 11000 | G13: 1 | H13: 0 | I13: 11000 | J13: 0 | K13: 11000 | L13: 0 | M13: 11000 | N13: Transfer Bank | O13: Completed | P13: FoodMart | Q13: 4 | R13: Perempuan
A14: ORD01811 | B14: 45995.485 | C14: Gita Saputra | D14: Bengkulu | E14: Timun | F14: 11000 | G14: 2.3 | H14: 0 | I14: 25300 | J14: 0 | K14: 25300 | L14: 72000 | M14: 97300 | N14: Kartu Kredit | O14: Pending | P14: FoodMart | Q14: 5 | R14: Perempuan
A15: ORD00558 | B15: 45990.404 | C15: Bella Iskandar | D15: Kendari | E15: Timun | F15: 11000 | G15: 1.7 | H15: 0 | I15: 18700 | J15: 0 | K15: 18700 | L15: 59000 | M15: 77700 | N15: Kartu Kredit | O15: Completed | P15: Karirnex VegMart App | Q15: 2 | R15: Perempuan
... A88: ORD00104 | B88: 45683.569 | C88: Sari Syahputra | D88: Merauke | E88: Timun | F88: 11000 | G88: 1.5 | H88: 0 | I88: 16500 | J88: 0 | K88: 16500 | L88: 0 | M88: 16500 | N88: Transfer Bank | O88: Returned | P88: FoodMart | Q88: 2 | R88: Perempuan

Sheet bahan
A3: Row Labels | B3: Sum of Total Sales | D3: Row Labels | E3: Sum of Total Sales
A4: 2025 | B4: 56433562 | D4: Jan | E4: 5008055
A5: Qtr1 | B5: 14245240 | D5: Feb | E5: 4411592.5
A6: Jan | B6: 5008055 | D6: Mar | E6: 4825592.5
A7: 01-Jan | B7: 195225 | D7: Apr | E7: 4320902.5
A8: 09 | B8: 10450 | D8: May | E8: 3903452.5
A9: :13 | B9: 10450 | D9: Jun | E9: 4721585
A10: :36 | B10: 10450 | D10: Jul | E10: 4132577.5
A11: 45658.384 | B11: 10450 | D11: Aug | E11: 4755047.5
A12: 10 | B12: 9975 | D12: Sep | E12: 3912375
A13: :09 | B13: 9975 | D13: Oct | E13: 4906020
A14: :49 | B14: 9975 | D14: Nov | E14: 5361720
A15: 45658.423 | B15: 9975 | D15: Dec | E15: 6174642.5 | AA15: Row Labels | AB15: Sum of Grand Total | AF15: Count of Order ID | AG15: Column Labels
A16: 12 | B16: 56335 | D16: Grand Total | E16: 56433562 | R16: Row Labels | S16: Count of Order ID | T16: Sum of Total Sales | AA16: BelanjaSayur App | AB16: 31724182 | AF16: Row Labels | AG16: Laki-laki | AH16: Perempuan | AI16: Grand Total
A17: :15 | B17: 19142.5 | R17: COD | S17: 499 | T17: 13086288 | V17: Row Labels | W17: Average of Customer Rating | X17: Count of Order ID | AA17: FoodMart | AB17: 31504552 | AF17: COD | AG17: 110 | AH17: 389 | AI17: 499
A18: :11 | B18: 19142.5 | R18: e-Wallet | S18: 467 | T18: 13574115 | V18: Bawang Merah | W18: 3.1666667 | X18: 156 | AA18: Hijau Mart | AB18: 32251402 | AF18: e-Wallet | AG18: 88 | AH18: 379 | AI18: 467
A19: 45658.511 | B19: 19142.5 | R19: Kartu Kredit | S19: 519 | T19: 14688805 | V19: Bawang Putih | W19: 2.8934911 | X19: 169 | AA19: Karirnex VegMart App | AB19: 31749498 | AF19: Kartu Kredit | AG19: 107 | AH19: 412 | AI19: 519
A20: :48 | B20: 37192.5 | R20: Transfer Bank | S20: 515 | T20: 15084355 | V20: Bayam | W20: 2.9 | X20: 80 | AA20: SayurKota Mart | AB20: 32254928 | AF20: Transfer Bank | AG20: 94 | AH20: 421 | AI20: 515 | AM20: Row Labels | AN20: Count of Order ID
A21: :33 | B21: 37192.5 | R21: Grand Total | S21: 2000 | T21: 56433562 | V21: Brokoli | W21: 2.9264706 | X21: 68 | AA21: Grand Total | AB21: 1.5948456e+08 | AF21: Grand Total | AG21: 399 | AH21: 1601 | AI21: 2000 | AM21: 0.1 | AN21: 6
A22: 45658.534 | B22: 37192.5 | V22: Buncis | W22: 3.1025641 | X22: 78 | AM22: 0.2 | AN22: 44
A23: 16 | B23: 45600 | V23: Cabai Merah | W23: 2.7966102 | X23: 118 | AA23: =AA15 -> Row Labels | AB23: =AB15 -> Sum of Grand Total | AM23: 0.3 | AN23: 64
A24: :28 | B24: 45600 | V24: Cabai Rawit Hijau | W24: 2.7931034 | X24: 87 | AA24: =AA16 -> BelanjaSayur App | AB24: =AB16 -> 31724182 | AM24: 0.4 | AN24: 115
A25: :10 | B25: 45600 | V25: Cabai Rawit Merah | W25: 3.1428571 | X25: 84 | AA25: =AA17 -> FoodMart | AB25: =AB17 -> 31504552 | AM25: 0.5 | AN25: 121
A26: 45658.686 | B26: 45600 | V26: Daun Bawang | W26: 2.8307692 | X26: 65 | AA26: =AA18 -> Hijau Mart | AB26: =AB18 -> 32251402 | AM26: 0.6 | AN26: 123
A27: 17 | B27: 21945 | V27: Jagung Manis | W27: 3.0560748 | X27: 107 | AA27: =AA19 -> Karirnex VegMart App | AB27: =AB19 -> 31749498 | AM27: 0.7 | AN27: 117
A28: :40 | B28: 21945 | V28: Kacang Panjang | W28: 3.0222222 | X28: 90 | AA28: =AA20 -> SayurKota Mart | AB28: =AB20 -> 32254928 | AM28: 0.8 | AN28: 104
A29: :15 | B29: 21945 | V29: Kangkung | W29: 3.175 | X29: 80 | AA29: =AA21 -> Grand Total | AB29: =AB21 -> 1.5948456e+08 | AM29: 0.9 | AN29: 124
A30: 45658.736 | B30: 21945 | V30: Kentang | W30: 2.8705036 | X30: 139 | AM30: 1 | AN30: 134
A31: 19 | B31: 50920 | V31: Kol/Kubis | W31: 2.8103448 | X31: 116 | AM31: 1.1 | AN31: 112
A32: :06 | B32: 29640 | V32: Labu Siam | W32: 3.0540541 | X32: 74 | AM32: 1.2 | AN32: 107
A33: :00 | B33: 29640 | V33: Sawi Hijau | W33: 3.0352941 | X33: 85 | AM33: 1.3 | AN33: 100
A34: 45658.796 | B34: 29640 | V34: Terong Ungu | W34: 2.7222222 | X34: 72 | AM34: 1.4 | AN34: 82
A35: :19 | B35: 21280 | V35: Timun | W35: 2.8117647 | X35: 85 | AM35: 1.5 | AN35: 78
A36: :14 | B36: 21280 | V36: Tomat Merah | W36: 3.3785714 | X36: 140 | AM36: 1.6 | AN36: 72
A37: 45658.805 | B37: 21280 | V37: Wortel | W37: 2.9345794 | X37: 107 | AM37: 1.7 | AN37: 55
A38: 02-Jan | B38: 145550 | AM38: 1.8 | AN38: 57
A39: 11 | B39: 64750 | W39: =W17 -> Average of Customer Rating | X39: =X17 -> Count of Order ID | AG39: Row Labels | AH39: Average of Shipping Fee | AM39: 1.9 | AN39: 43
A40: :20 | B40: 64750 | W40: =W18 -> 3.1666667 | X40: =X18 -> 156 | AG40: Nabire | AH40: 86880.952 | AM40: 2 | AN40: 33
A41: :56 | B41: 64750 | W41: =W19 -> 2.8934911 | X41: =X19 -> 169 | AG41: Jakarta | AH41: 86640.777 | AM41: 2.1 | AN41: 34
A42: 45659.473 | B42: 64750 | W42: =W20 -> 2.9 | X42: =X20 -> 80 | AG42: Manado | AH42: 84348.837 | AM42: 2.2 | AN42: 32
...

Sheet Detail2
A1: Details for - Hours (Order Date): 5, hari: Sun
A3: Order ID | B3: Order Date | C3: Customer Name | D3: City | E3: Product Name | F3: Unit Price | G3: Quantity (kg) | H3: Discount (%) | I3: Subtotal | J3: Discount Amount | K3: Total Sales | L3: Shipping Fee | M3: Grand Total | N3: Payment Method | O3: Order Status | P3: Platform | Q3: Customer Rating | R3: Jenis Kelamin | S3: hari
A4: ORD00075 | B4: 45823.213 | C4: Iwan Maulana | D4: Pontianak | E4: Kentang | F4: 17500 | G4: 1.2 | H4: 0 | I4: 21000 | J4: 0 | K4: 21000 | L4: 85000 | M4: 106000 | N4: e-Wallet | O4: Cancelled | P4: BelanjaSayur App | Q4: 5 | R4: Laki-laki | S4: Sun

Sheet bahanlagi
B2: Sum of Shipping Fee | D2: Sum of Total Sales | F2: Sum of Grand Total | H2: Sum of Shipping Fee | J2: Average of Customer Rating | L2: Count of Order ID
B3: 103051000 | D3: 56433562 | F3: 1.5948456e+08 | H3: 103051000 | J3: 2.9805 | L3: 2000
B5: =GETPIVOTDATA("Shipping Fee",$B$2) -> 103051000 | D5: =GETPIVOTDATA("Total Sales",$D$2) -> 56433562 | F5: =GETPIVOTDATA("Grand Total",$F$2) -> 1.5948456e+08 | H5: =GETPIVOTDATA("Shipping Fee",$H$2) -> 103051000 | J5: =GETPIVOTDATA("Customer Rating",$J$2) -> 2.9805 | L5: =GETPIVOTDATA("Order ID",$L$2) -> 2000
V6: Days
U7: Hours | V7: Sun | W7: Mon | X7: Tue | Y7: Wed | Z7: Thu | AA7: Fri | AB7: Sat
D8: Row Labels | E8: Count of Order ID | U8: 00 | V8: 5 | W8: 4 | X8: 3 | Y8: 5 | Z8: 2 | AA8: 8 | AB8: 5
D9: Karirnex VegMart App | E9: 409 | G9: Sum of Discount Amount | U9: 01 | V9: 3 | W9: 2 | X9: 11 | Y9: 8 | Z9: 7 | AA9: 3 | AB9: 6
D10: Hijau Mart | E10: 402 | G10: 587387.5 | U10: 02 | V10: 6 | W10: 6 | X10: 1 | Y10: 3 | Z10: 4 | AA10: 11 | AB10: 2
D11: BelanjaSayur App | E11: 399 | U11: 03 | V11: 4 | W11: 9 | X11: 2 | Y11: 3 | Z11: 5 | AA11: 3 | AB11: 5
D12: SayurKota Mart | E12: 396 | U12: 04 | V12: 3 | W12: 2 | X12: 3 | Y12: 3 | Z12: 2 | AA12: 6 | AB12: 4
D13: FoodMart | E13: 394 | U13: 05 | V13: 1 | W13: 1 | X13: 2 | Y13: 3 | Z13: 4 | AA13: 6 | AB13: 4
D14: Grand Total | E14: 2000 | G14: Row Labels | H14: Count of Order ID | U14: 06 | V14: 5 | W14: 11 | X14: 9 | Y14: 7 | Z14: 5 | AA14: 7 | AB14: 9
G15: COD | H15: 499 | U15: 07 | V15: 9 | W15: 13 | X15: 8 | Y15: 4 | Z15: 9 | AA15: 8 | AB15: 8
G16: e-Wallet | H16: 467 | U16: 08 | V16: 8 | W16: 8 | X16: 10 | Y16: 8 | Z16: 11 | AA16: 19 | AB16: 11
G17: Kartu Kredit | H17: 519 | U17: 09 | V17: 19 | W17: 12 | X17: 17 | Y17: 13 | Z17: 19 | AA17: 24 | AB17: 19
G18: Transfer Bank | H18: 515 | J18: Row Labels | K18: Sum of Total Sales | U18: 10 | V18: 19 | W18: 23 | X18: 28 | Y18: 27 | Z18: 22 | AA18: 18 | AB18: 20
G19: Grand Total | H19: 2000 | J19: Jakarta | K19: 2835992.5 | U19: 11 | V19: 25 | W19: 21 | X19: 30 | Y19: 17 | Z19: 17 | AA19: 23 | AB19: 20
J20: Pangkalpinang | K20: 2557985 | U20: 12 | V20: 25 | W20: 15 | X20: 23 | Y20: 16 | Z20: 19 | AA20: 35 | AB20: 29
J21: Pontianak | K21: 2206555 | U21: 13 | V21: 24 | W21: 25 | X21: 26 | Y21: 15 | Z21: 30 | AA21: 23 | AB21: 12
J22: Jayapura | K22: 2180035 | U22: 14 | V22: 22 | W22: 21 | X22: 18 | Y22: 18 | Z22: 17 | AA22: 20 | AB22: 23
J23: Surabaya | K23: 2086342.5 | U23: 15 | V23: 17 | W23: 18 | X23: 38 | Y23: 13 | Z23: 18 | AA23: 26 | AB23: 18
J24: Samarinda | K24: 2058855 | U24: 16 | V24: 10 | W24: 17 | X24: 23 | Y24: 20 | Z24: 16 | AA24: 19 | AB24: 10
J25: Manokwari | K25: 1944560 | U25: 17 | V25: 20 | W25: 16 | X25: 26 | Y25: 17 | Z25: 27 | AA25: 16 | AB25: 17
J26: Semarang | K26: 1851255 | U26: 18 | V26: 16 | W26: 13 | X26: 14 | Y26: 9 | Z26: 12 | AA26: 11 | AB26: 18
J27: Wamena | K27: 1843730 | U27: 19 | V27: 10 | W27: 13 | X27: 9 | Y27: 9 | Z27: 12 | AA27: 17 | AB27: 13
J28: Bengkulu | K28: 1815765 | U28: 20 | V28: 8 | W28: 4 | X28: 7 | Y28: 6 | Z28: 8 | AA28: 14 | AB28: 4
J29: Tanjungpinang | K29: 1809527.5 | U29: 21 | V29: 18 | W29: 6 | X29: 6 | Y29: 8 | Z29: 16 | AA29: 6 | AB29: 3
J30: Yogyakarta | K30: 1762142.5 | U30: 22 | V30: 5 | W30: 4 | X30: 2 | Y30: 7 | Z30: 6 | AA30: 3 | AB30: 3
J31: Bandung | K31: 1741747.5 | U31: 23 | V31: 3 | W31: 4 | X31: 3 | Y31: 1 | Z31: 4 | AA31: 3 | AB31: 4
J32: Sorong | K32: 1734125
J33: Tanjung Selor | K33: 1727035
J34: Mataram | K34: 1686855
J35: Banda Aceh | K35: 1618552.5
J36: Kendari | K36: 1569360
E37: Row Labels | F37: Count of Order ID | J37: Jambi | K37: 1555272.5
E38: Laki-laki | F38: 399 | J38: Medan | K38: 1409237.5
E39: Perempuan | F39: 1601 | J39: Pekanbaru | K39: 1384285
E40: Grand Total | F40: 2000 | J40: Palu | K40: 1319277.5
J41: Mamuju | K41: 1239475
J42: Palembang | K42: 1226547.5
...

Sheet dashboard

Sheet Sheet1
A3: Count of Order ID | B3: hari
A4: Hours (Order Date) | B4: Sun | C4: Mon | D4: Tue | E4: Wed | F4: Thu | G4: Fri | H4: Sat
A5: 00 | B5: 5 | C5: 4 | D5: 3 | E5: 5 | F5: 2 | G5: 8 | H5: 5
A6: 01 | B6: 3 | C6: 2 | D6: 11 | E6: 8 | F6: 7 | G6: 3 | H6: 6
A7: 02 | B7: 6 | C7: 6 | D7: 1 | E7: 3 | F7: 4 | G7: 11 | H7: 2
A8: 03 | B8: 4 | C8: 9 | D8: 2 | E8: 3 | F8: 5 | G8: 3 | H8: 5
A9: 04 | B9: 3 | C9: 2 | D9: 3 | E9: 3 | F9: 2 | G9: 6 | H9: 4
A10: 05 | B10: 1 | C10: 1 | D10: 2 | E10: 3 | F10: 4 | G10: 6 | H10: 4
A11: 06 | B11: 5 | C11: 11 | D11: 9 | E11: 7 | F11: 5 | G11: 7 | H11: 9
A12: 07 | B12: 9 | C12: 13 | D12: 8 | E12: 4 | F12: 9 | G12: 8 | H12: 8
A13: 08 | B13: 8 | C13: 8 | D13: 10 | E13: 8 | F13: 11 | G13: 19 | H13: 11
A14: 09 | B14: 19 | C14: 12 | D14: 17 | E14: 13 | F14: 19 | G14: 24 | H14: 19
A15: 10 | B15: 19 | C15: 23 | D15: 28 | E15: 27 | F15: 22 | G15: 18 | H15: 20
A16: 11 | B16: 25 | C16: 21 | D16: 30 | E16: 17 | F16: 17 | G16: 23 | H16: 20
... A28: 23 | B28: 3 | C28: 4 | D28: 3 | E28: 1 | F28: 4 | G28: 3 | H28: 4

Sheet Data
A1: Karirnex VegMart App
A2: Toko Sayur Sehat, Segar dan Awet, Melayani Permintaan di Seluruh Indonesia | U2: jmlh perempuan
A3: Order ID | B3: Order Date | C3: Customer Name | D3: City | E3: Product Name | F3: Unit Price | G3: Quantity (kg) | H3: Discount (%) | I3: Subtotal | J3: Discount Amount | K3: Total Sales | L3: Shipping Fee | M3: Grand Total | N3: Payment Method | O3: Order Status | P3: Platform | Q3: Customer Rating | R3: Jenis Kelamin | S3: hari | T3: order status2 | U3: =COUNTIFS(R4:R2003,"Perempuan") -> 1601
A4: ORD01855 | B4: 45658.384 | C4: Zahra Kurniawan | D4: Wamena | E4: Jagung Manis | F4: 10000 | G4: 1.1 | H4: 5 | I4: =F4*G4 -> 11000 | J4: =I4*(H4/100) -> 550 | K4: =I4-J4 -> 10450 | L4: 15000 | M4: =K4+L4 -> 25450 | N4: Kartu Kredit | O4: Completed | P4: Hijau Mart | Q4: 3 | R4: Perempuan | S4: =TEXT(B4,"DDD") -> Wed | T4: =VLOOKUP(A4,Status!$A$2:$B$1867,2,FALSE) -> Completed
A5: ORD01741 | B5: 45658.423 | C5: Yani Pradipta | D5: Palembang | E5: Sawi Hijau | F5: 15000 | G5: 0.7 | H5: 5 | I5: =F5*G5 -> 10500 | J5: =I5*(H5/100) -> 525 | K5: =I5-J5 -> 9975 | L5: 17000 | M5: =K5+L5 -> 26975 | N5: Transfer Bank | O5: Completed | P5: SayurKota Mart | Q5: 5 | R5: Perempuan | S5: =TEXT(B5,"DDD") -> Wed | T5: =VLOOKUP(A5,Status!$A$2:$B$1867,2,FALSE) -> Completed | U5: perempuan rating 5
A6: ORD00016 | B6: 45658.511 | C6: Indra Syahputra | D6: Semarang | E6: Wortel | F6: 20000 | G6: 0.4 | H6: 5 | I6: =F6*G6 -> 8000 | J6: =I6*(H6/100) -> 400 | K6: =I6-J6 -> 7600 | L6: 76000 | M6: =K6+L6 -> 83600 | N6: COD | O6: Completed | P6: FoodMart | Q6: 1 | R6: Laki-laki | S6: =TEXT(B6,"DDD") -> Wed | T6: =VLOOKUP(A6,Status!$A$2:$B$1867,2,FALSE) -> Completed
A7: ORD00016 | B7: 45658.511 | C7: Indra Syahputra | D7: Semarang | E7: Kol/Kubis | F7: 13500 | G7: 0.9 | H7: 5 | I7: =F7*G7 -> 12150 | J7: =I7*(H7/100) -> 607.5 | K7: =I7-J7 -> 11542.5 | L7: 0 | M7: =K7+L7 -> 11542.5 | N7: COD | O7: Completed | P7: FoodMart | Q7: 1 | R7: Laki-laki | S7: =TEXT(B7,"DDD") -> Wed | T7: =VLOOKUP(A7,Status!$A$2:$B$1867,2,FALSE) -> Completed | U7: =COUNTIFS(R4:R2003,"Perempuan",Q4:Q2003,5) -> 301
A8: ORD00411 | B8: 45658.534 | C8: Yani Nugroho | D8: Palembang | E8: Kol/Kubis | F8: 13500 | G8: 2.9 | H8: 5 | I8: =F8*G8 -> 39150 | J8: =I8*(H8/100) -> 1957.5 | K8: =I8-J8 -> 37192.5 | L8: 17000 | M8: =K8+L8 -> 54192.5 | N8: Transfer Bank | O8: Completed | P8: SayurKota Mart | Q8: 2 | R8: Perempuan | S8: =TEXT(B8,"DDD") -> Wed | T8: =VLOOKUP(A8,Status!$A$2:$B$1867,2,FALSE) -> Completed
A9: ORD00326 | B9: 45658.686 | C9: Lestari Utami | D9: Manado | E9: Bawang Putih | F9: 40000 | G9: 1.2 | H9: 5 | I9: =F9*G9 -> 48000 | J9: =I9*(H9/100) -> 2400 | K9: =I9-J9 -> 45600 | L9: 93000 | M9: =K9+L9 -> 138600 | N9: COD | O9: Completed | P9: Karirnex VegMart App | Q9: 2 | R9: Perempuan | S9: =TEXT(B9,"DDD") -> Wed | T9: =VLOOKUP(A9,Status!$A$2:$B$1867,2,FALSE) -> Completed | U9: rata-rata subtotal di kota mataram
A10: ORD01208 | B10: 45658.736 | C10: Erna Santoso | D10: Samarinda | E10: Labu Siam | F10: 10500 | G10: 2.2 | H10: 5 | I10: =F10*G10 -> 23100 | J10: =I10*(H10/100) -> 1155 | K10: =I10-J10 -> 21945 | L10: 43000 | M10: =K10+L10 -> 64945 | N10: Kartu Kredit | O10: Completed | P10: SayurKota Mart | Q10: 4 | R10: Perempuan | S10: =TEXT(B10,"DDD") -> Wed | T10: =VLOOKUP(A10,Status!$A$2:$B$1867,2,FALSE) -> Completed | U10: =AVERAGEIFS(I4:I2003,D4:D2003,"Mataram") -> 29819.298
A11: ORD01664 | B11: 45658.796 | C11: Erna Rahmawati | D11: Banda Aceh | E11: Brokoli | F11: 26000 | G11: 1.2 | H11: 5 | I11: =F11*G11 -> 31200 | J11: =I11*(H11/100) -> 1560 | K11: =I11-J11 -> 29640 | L11: 18000 | M11: =K11+L11 -> 47640 | N11: Transfer Bank | O11: Completed | P11: SayurKota Mart | Q11: 5 | R11: Perempuan | S11: =TEXT(B11,"DDD") -> Wed | T11: =VLOOKUP(A11,Status!$A$2:$B$1867,2,FALSE) -> Completed
A12: ORD00644 | B12: 45658.805 | C12: Erna Setiawan | D12: Denpasar | E12: Buncis | F12: 14000 | G12: 1.6 | H12: 5 | I12: =F12*G12 -> 22400 | J12: =I12*(H12/100) -> 1120 | K12: =I12-J12 -> 21280 | L12: 80000 | M12: =K12+L12 -> 101280 | N12: COD | O12: Completed | P12: FoodMart | Q12: 5 | R12: Perempuan | S12: =TEXT(B12,"DDD") -> Wed | T12: =VLOOKUP(A12,Status!$A$2:$B$1867,2,FALSE) -> Completed | U12: rata-rata subtotal di kota mataram dan payment method cod
A13: ORD00628 | B13: 45659.473 | C13: Bella Santoso | D13: Tanjung Selor | E13: Kentang | F13: 17500 | G13: 3.7 | H13: 0 | I13: =F13*G13 -> 64750 | J13: =I13*(H13/100) -> 0 | K13: =I13-J13 -> 64750 | L13: 26000 | M13: =K13+L13 -> 90750 | N13: e-Wallet | O13: Completed | P13: FoodMart | Q13: 2 | R13: Perempuan | S13: =TEXT(B13,"DDD") -> Thu | T13: =VLOOKUP(A13,Status!$A$2:$B$1867,2,FALSE) -> Completed | U13: =AVERAGEIFS(I4:I2003,D4:D2003,"Mataram",N4:N2003,"COD") -> 30670
A14: ORD00049 | B14: 45659.514 | C14: Joko Halim | D14: Kendari | E14: Jagung Manis | F14: 10000 | G14: 2.1 | H14: 0 | I14: =F14*G14 -> 21000 | J14: =I14*(H14/100) -> 0 | K14: =I14-J14 -> 21000 | L14: 59000 | M14: =K14+L14 -> 80000 | N14: e-Wallet | O14: Completed | P14: FoodMart | Q14: 1 | R14: Laki-laki | S14: =TEXT(B14,"DDD") -> Thu | T14: =VLOOKUP(A14,Status!$A$2:$B$1867,2,FALSE) -> Completed
A15: ORD00634 | B15: 45659.656 | C15: Fajar Budiman | D15: Nabire | E15: Cabai Merah | F15: 46000 | G15: 1.3 | H15: 0 | I15: =F15*G15 -> 59800 | J15: =I15*(H15/100) -> 0 | K15: =I15-J15 -> 59800 | L15: 89000 | M15: =K15+L15 -> 148800 | N15: COD | O15: Completed | P15: Karirnex VegMart App | Q15: 1 | R15: Laki-laki | S15: =TEXT(B15,"DDD") -> Thu | T15: =VLOOKUP(A15,Status!$A$2:$B$1867,2,FALSE) -> Completed | U15: brp banyak qty yg berbelanja di belanjasayur app
A16: ORD00954 | B16: 45660.15 | C16: Vina Ramadhani | D16: Jambi | E16: Jagung Manis | F16: 10000 | G16: 2.5 | H16: 0 | I16: =F16*G16 -> 25000 | J16: =I16*(H16/100) -> 0 | K16: =I16-J16 -> 25000 | L16: 87000 | M16: =K16+L16 -> 112000 | N16: COD | O16: Returned | P16: SayurKota Mart | Q16: 4 | R16: Perempuan | S16: =TEXT(B16,"DDD") -> Fri | T16: =VLOOKUP(A16,Status!$A$2:$B$1867,2,FALSE) -> Returned | U16: =SUMIFS(G4:G2003,P4:P2003,P18) -> 475.6
A17: ORD00844 | B17: 45660.671 | C17: Lestari Setiawan | D17: Tanjung Selor | E17: Wortel | F17: 20000 | G17: 1.3 | H17: 0 | I17: =F17*G17 -> 26000 | J17: =I17*(H17/100) -> 0 | K17: =I17-J17 -> 26000 | L17: 26000 | M17: =K17+L17 -> 52000 | N17: COD | O17: Completed | P17: Karirnex VegMart App | Q17: 4 | R17: Perempuan | S17: =TEXT(B17,"DDD") -> Fri | T17: =VLOOKUP(A17,Status!$A$2:$B$1867,2,FALSE) -> Completed
A18: ORD00946 | B18: 45661.406 | C18: Aulia Iskandar | D18: Surabaya | E18: Bawang Merah | F18: 45000 | G18: 0.6 | H18: 0 | I18: =F18*G18 -> 27000 | J18: =I18*(H18/100) -> 0 | K18: =I18-J18 -> 27000 | L18: 74000 | M18: =K18+L18 -> 101000 | N18: Transfer Bank | O18: Completed | P18: BelanjaSayur App | Q18: 2 | R18: Perempuan | S18: =TEXT(B18,"DDD") -> Sat | T18: =VLOOKUP(A18,Status!$A$2:$B$1867,2,FALSE) -> Completed | U18: brp banyak qty yg berbelanja di belanjasayur app jenis kelamin laki
A19: ORD00051 | B19: 45661.448 | C19: Made Setiawan | D19: Denpasar | E19: Bawang Putih | F19: 40000 | G19: 0.5 | H19: 0 | I19: =F19*G19 -> 20000 | J19: =I19*(H19/100) -> 0 | K19: =I19-J19 -> 20000 | L19: 80000 | M19: =K19+L19 -> 100000 | N19: Kartu Kredit | O19: Completed | P19: SayurKota Mart | Q19: 2 | R19: Laki-laki | S19: =TEXT(B19,"DDD") -> Sat | T19: =VLOOKUP(A19,Status!$A$2:$B$1867,2,FALSE) -> Completed | U19: =SUMIFS(G4:G2003,P4:P2003,P20,R4:R2003,"Laki-laki") -> 71.9
A20: ORD00559 | B20: 45661.491 | C20: Qori Fauziah | D20: Surabaya | E20: Tomat Merah | F20: 15000 | G20: 1.3 | H20: 0 | I20: =F20*G20 -> 19500 | J20: =I20*(H20/100) -> 0 | K20: =I20-J20 -> 19500 | L20: 74000 | M20: =K20+L20 -> 93500 | N20: COD | O20: Completed | P20: BelanjaSayur App | Q20: 4 | R20: Perempuan | S20: =TEXT(B20,"DDD") -> Sat | T20: =VLOOKUP(A20,Status!$A$2:$B$1867,2,FALSE) -> Completed
A21: ORD01530 | B21: 45661.75 | C21: Lestari Setiawan | D21: Tanjung Selor | E21: Tomat Merah | F21: 15000 | G21: 0.5 | H21: 0 | I21: =F21*G21 -> 7500 | J21: =I21*(H21/100) -> 0 | K21: =I21-J21 -> 7500 | L21: 26000 | M21: =K21+L21 -> 33500 | N21: Transfer Bank | O21: Completed | P21: FoodMart | Q21: 4 | R21: Perempuan | S21: =TEXT(B21,"DDD") -> Sat | T21: =VLOOKUP(A21,Status!$A$2:$B$1867,2,FALSE) -> Completed | U21: brp banyak qty yg berbelanja di belanjasayur app jenis kelamin perempuan
A22: ORD01160 | B22: 45661.768 | C22: Yani Saputra | D22: Jayapura | E22: Kentang | F22: 17500 | G22: 2.6 | H22: 0 | I22: =F22*G22 -> 45500 | J22: =I22*(H22/100) -> 0 | K22: =I22-J22 -> 45500 | L22: 30000 | M22: =K22+L22 -> 75500 | N22: e-Wallet | O22: Completed | P22: BelanjaSayur App | Q22: 2 | R22: Perempuan | S22: =TEXT(B22,"DDD") -> Sat | T22: =VLOOKUP(A22,Status!$A$2:$B$1867,2,FALSE) -> Completed | U22: =SUMIFS(G4:G2003,P4:P2003,P18,R4:R2003,"Perempuan") -> 403.7
A23: ORD01060 | B23: 45661.832 | C23: Qori Halim | D23: Pekanbaru | E23: Kol/Kubis | F23: 13500 | G23: 1.7 | H23: 0 | I23: =F23*G23 -> 22950 | J23: =I23*(H23/100) -> 0 | K23: =I23-J23 -> 22950 | L23: 49000 | M23: =K23+L23 -> 71950 | N23: Kartu Kredit | O23: Completed | P23: SayurKota Mart | Q23: 1 | R23: Perempuan | S23: =TEXT(B23,"DDD") -> Sat | T23: =VLOOKUP(A23,Status!$A$2:$B$1867,2,FALSE) -> Completed
A24: ORD00181 | B24: 45661.924 | C24: Gita Hidayat | D24: Jayapura | E24: Bawang Putih | F24: 40000 | G24: 1.8 | H24: 0 | I24: =F24*G24 -> 72000 | J24: =I24*(H24/100) -> 0 | K24: =I24-J24 -> 72000 | L24: 30000 | M24: =K24+L24 -> 102000 | N24: Transfer Bank | O24: Completed | P24: SayurKota Mart | Q24: 5 | R24: Perempuan | S24: =TEXT(B24,"DDD") -> Sat | T24: =VLOOKUP(A24,Status!$A$2:$B$1867,2,FALSE) -> Completed
A25: ORD01730 | B25: 45662.723 | C25: Bella Rahmawati | D25: Kendari | E25: Kentang | F25: 17500 | G25: 2.6 | H25: 0 | I25: =F25*G25 -> 45500 | J25: =I25*(H25/100) -> 0 | K25: =I25-J25 -> 45500 | L25: 59000 | M25: =K25+L25 -> 104500 | N25: Transfer Bank | O25: Returned | P25: Karirnex VegMart App | Q25: 3 | R25: Perempuan | S25: =TEXT(B25,"DDD") -> Sun | T25: =VLOOKUP(A25,Status!$A$2:$B$1867,2,FALSE) -> Returned
A26: ORD01668 | B26: 45662.771 | C26: Bella Ramadhani | D26: Pontianak | E26: Terong Ungu | F26: 9500 | G26: 2.1 | H26: 0 | I26: =F26*G26 -> 19950 | J26: =I26*(H26/100) -> 0 | K26: =I26-J26 -> 19950 | L26: 85000 | M26: =K26+L26 -> 104950 | N26: Kartu Kredit | O26: Completed | P26: Hijau Mart | Q26: 5 | R26: Perempuan | S26: =TEXT(B26,"DDD") -> Sun | T26: =VLOOKUP(A26,Status!$A$2:$B$1867,2,FALSE) -> Completed
A27: ORD01529 | B27: 45662.896 | C27: Hana Budiman | D27: Jakarta | E27: Kangkung | F27: 10000 | G27: 1 | H27: 0 | I27: =F27*G27 -> 10000 | J27: =I27*(H27/100) -> 0 | K27: =I27-J27 -> 10000 | L27: 97000 | M27: =K27+L27 -> 107000 | N27: e-Wallet | O27: Completed | P27: FoodMart | Q27: 1 | R27: Perempuan | S27: =TEXT(B27,"DDD") -> Sun | T27: =VLOOKUP(A27,Status!$A$2:$B$1867,2,FALSE) -> Completed
A28: ORD01671 | B28: 45666.855 | C28: Vina Budiman | D28: Samarinda | E28: Cabai Rawit Hijau | F28: 55000 | G28: 0.5 | H28: 0 | I28: =F28*G28 -> 27500 | J28: =I28*(H28/100) -> 0 | K28: =I28-J28 -> 27500 | L28: 43000 | M28: =K28+L28 -> 70500 | N28: Kartu Kredit | O28: Completed | P28: BelanjaSayur App | Q28: 4 | R28: Perempuan | S28: =TEXT(B28,"DDD") -> Thu | T28: =VLOOKUP(A28,Status!$A$2:$B$1867,2,FALSE) -> Completed
A29: ORD00239 | B29: 45666.899 | C29: Vina Puspita | D29: Manokwari | E29: Cabai Rawit Hijau | F29: 55000 | G29: 1.1 | H29: 0 | I29: =F29*G29 -> 60500 | J29: =I29*(H29/100) -> 0 | K29: =I29-J29 -> 60500 | L29: 18000 | M29: =K29+L29 -> 78500 | N29: Transfer Bank | O29: Completed | P29: Karirnex VegMart App | Q29: 1 | R29: Perempuan | S29: =TEXT(B29,"DDD") -> Thu | T29: =VLOOKUP(A29,Status!$A$2:$B$1867,2,FALSE) -> Completed
A30: ORD00403 | B30: 45667.41 | C30: Zahra Rahmawati | D30: Bengkulu | E30: Labu Siam | F30: 10500 | G30: 1.3 | H30: 0 | I30: =F30*G30 -> 13650 | J30: =I30*(H30/100) -> 0 | K30: =I30-J30 -> 13650 | L30: 72000 | M30: =K30+L30 -> 85650 | N30: e-Wallet | O30: Completed | P30: Hijau Mart | Q30: 4 | R30: Perempuan | S30: =TEXT(B30,"DDD") -> Fri | T30: =VLOOKUP(A30,Status!$A$2:$B$1867,2,FALSE) -> Completed
A31: ORD00933 | B31: 45668.259 | C31: Lestari Wijaya | D31: Bandung | E31: Labu Siam | F31: 10500 | G31: 1.3 | H31: 0 | I31: =F31*G31 -> 13650 | J31: =I31*(H31/100) -> 0 | K31: =I31-J31 -> 13650 | L31: 0 | M31: =K31+L31 -> 13650 | N31: Kartu Kredit | O31: Completed | P31: Karirnex VegMart App | Q31: 2 | R31: Perempuan | S31: =TEXT(B31,"DDD") -> Sat | T31: =VLOOKUP(A31,Status!$A$2:$B$1867,2,FALSE) -> Completed
A32: ORD01507 | B32: 45668.399 | C32: Vina Kurniawan | D32: Yogyakarta | E32: Labu Siam | F32: 10500 | G32: 1.6 | H32: 0 | I32: =F32*G32 -> 16800 | J32: =I32*(H32/100) -> 0 | K32: =I32-J32 -> 16800 | L32: 78000 | M32: =K32+L32 -> 94800 | N32: Transfer Bank | O32: Cancelled | P32: Hijau Mart | Q32: 3 | R32: Perempuan | S32: =TEXT(B32,"DDD") -> Sat | T32: =VLOOKUP(A32,Status!$A$2:$B$1867,2,FALSE) -> Cancelled
A33: ORD01414 | B33: 45668.528 | C33: Eka Ananda | D33: Makassar | E33: Cabai Rawit Hijau | F33: 55000 | G33: 0.4 | H33: 0 | I33: =F33*G33 -> 22000 | J33: =I33*(H33/100) -> 0 | K33: =I33-J33 -> 22000 | L33: 84000 | M33: =K33+L33 -> 106000 | N33: Transfer Bank | O33: Completed | P33: Karirnex VegMart App | Q33: 1 | R33: Perempuan | S33: =TEXT(B33,"DDD") -> Sat | T33: =VLOOKUP(A33,Status!$A$2:$B$1867,2,FALSE) -> Completed
A34: ORD00811 | B34: 45668.727 | C34: Nanda Iskandar | D34: Pontianak | E34: Sawi Hijau | F34: 15000 | G34: 0.9 | H34: 0 | I34: =F34*G34 -> 13500 | J34: =I34*(H34/100) -> 0 | K34: =I34-J34 -> 13500 | L34: 85000 | M34: =K34+L34 -> 98500 | N34: COD | O34: Completed | P34: Hijau Mart | Q34: 4 | R34: Laki-laki | S34: =TEXT(B34,"DDD") -> Sat | T34: =VLOOKUP(A34,Status!$A$2:$B$1867,2,FALSE) -> Completed
... A2003: ORD00553 | B2003: 46022.934 | C2003: Kartika Saputra | D2003: Palu | E2003: Kacang Panjang | F2003: 12000 | G2003: 1.1 | H2003: 0 | I2003: =F2003*G2003 -> 13200 | J2003: =I2003*(H2003/100) -> 0 | K2003: =I2003-J2003 -> 13200 | L2003: 67000 | M2003: =K2003+L2003 -> 80200 | N2003: Kartu Kredit | O2003: Shipped | P2003: BelanjaSayur App | Q2003: 3 | R2003: Perempuan | S2003: =TEXT(B2003,"DDD") -> Wed | T2003: =VLOOKUP(A2003,Status!$A$2:$B$1867,2,FALSE) -> Shipped

Sheet Status
A1: Order ID | B1: Order Status
A2: ORD00001 | B2: Returned
A3: ORD00002 | B3: Completed
A4: ORD00003 | B4: Returned
A5: ORD00004 | B5: Shipped
A6: ORD00005 | B6: Cancelled
A7: ORD00006 | B7: Completed
A8: ORD00007 | B8: Completed
A9: ORD00008 | B9: Returned
A10: ORD00009 | B10: Completed
A11: ORD00010 | B11: Completed
A12: ORD00011 | B12: Completed
... A1867: ORD01866 | B1867: Completed

Sheet Referensi Harga
A1: Produk Sayuran | B1: Harga Acuan (Rp/kg) | C1: Sumber | D1: URL Sumber | E1: Tanggal Acuan | F1: Catatan
A2: Bayam | B2: 10000 | C2: Info Pasar Denpasar - Pasar Badung | D2: https://infopasar.denpasarkota.go.id/ | E2: 46106 | F2: Harga per kg
A3: Kangkung | B3: 10000 | C3: Info Pasar Denpasar - Pasar Badung | D3: https://infopasar.denpasarkota.go.id/ | E3: 46106 | F3: Harga per kg
A4: Sawi Hijau | B4: 15000 | C4: Info Pasar Denpasar - Pasar Badung | D4: https://infopasar.denpasarkota.go.id/ | E4: 46106 | F4: Harga per kg
A5: Kacang Panjang | B5: 12000 | C5: Info Pasar Denpasar - Pasar Badung | D5: https://infopasar.denpasarkota.go.id/ | E5: 46106 | F5: Harga per kg
A6: Wortel | B6: 20000 | C6: Info Pasar Denpasar - Pasar Badung | D6: https://infopasar.denpasarkota.go.id/ | E6: 46106 | F6: Harga per kg
A7: Bawang Merah | B7: 45000 | C7: e-TUKU Kota Cirebon | D7: https://etuku.cirebonkota.go.id/ | E7: 46106 | F7: Harga rata-rata kota per kg, 25 Mar 2026
A8: Bawang Putih | B8: 40000 | C8: e-TUKU Kota Cirebon | D8: https://etuku.cirebonkota.go.id/ | E8: 46106 | F8: Harga rata-rata kota per kg, 25 Mar 2026
A9: Jagung Manis | B9: 10000 | C9: e-TUKU Kota Cirebon | D9: https://etuku.cirebonkota.go.id/ | E9: 46106 | F9: Harga rata-rata kota per kg, 25 Mar 2026
A10: Kentang | B10: 17500 | C10: e-TUKU Kota Cirebon | D10: https://etuku.cirebonkota.go.id/ | E10: 46106 | F10: Harga rata-rata kota per kg, 25 Mar 2026
A11: Kol/Kubis | B11: 13500 | C11: e-TUKU Kota Cirebon | D11: https://etuku.cirebonkota.go.id/ | E11: 46106 | F11: Harga rata-rata kota per kg, 25 Mar 2026
A12: Tomat Merah | B12: 15000 | C12: e-TUKU Kota Cirebon | D12: https://etuku.cirebonkota.go.id/ | E12: 46106 | F12: Harga rata-rata kota per kg, 25 Mar 2026
A13: Cabai Merah | B13: 46000 | C13: e-TUKU Kota Cirebon | D13: https://etuku.cirebonkota.go.id/ | E13: 46106 | F13: Harga rata-rata kota per kg, 25 Mar 2026
... A21: Daun Bawang | B21: 15500 | C21: SIHARTAPASTI Kota Tangerang | D21: https://sihartapasti.tangerangkota.go.id/ | E21: 46106 | F21: Harga rata-rata per kg, dibulatkan
A23: Catatan
A24: Harga acuan dipakai untuk membangun dummy data penjualan 2025, dengan kuantitas minimum 0,1 kg. Beberapa harga rata-rata pasar dibulatkan ke nominal pasar yang wajar.
